Workbook

Sheet Desejos e Cancelamentos
A1: SKU | B1: Produto | C1: Precisa de Certificação? | D1: Qual Certificação? | E1: Por que precisa certificar? | F1: NCM | G1: FAT | H1: Quando foi cancelado? | I1: Por que foi cancelado?
B2: Squishy Toy | C2: Não | F2: NOVA
B3: Apontador Elétrico | C3: Não | E3: Possui motor | F3: NOVA
B4: Patins IMG | C4: Não | F4: NOVA
B5: Patins Puket | C5: Sim | D5: INMETRO Brinquedos | E5: Destinado para Crianças | F5: NOVA
A6: PI4662Y | B6: MASCARA ANTI-IDADE | C6: Sim | D6: ANVISA Correlatos | E6: Produto para Saúde | F6: NOVA | G6: FAT 2 / 2021 | H6: 44074 | I6: Não possuímos uma AFE para produtos de saúde (correlatos), assim como não temos estimado a compra de produtos que entrem neste escopo num futuro próximo, desta forma os custos para obtenção da AFE de importação e distribuição, assim como os custos para ensaios (onde já tinhamos um problema do fornecedor não garantir a eficácia do produto), e também os custos para registro na ANVISA superavam os 30k, inviabilizando a compra deste produto
B7: Carregador luminaria dobrável | F7: NOVA | H7: 44063 | I7: Produto não tinha ISO 9001
B8: Maquina de Bolha de sabão | C8: Sim | D8: INMETRO Brinquedos | E8: Destinado para Crianças | F8: NOVA
B9: Termometro | C9: Não | F9: NOVA
B10: Pistola de dinheiro (impressora | C10: Sim | D10: INMETRO Brinquedos | F10: NOVA
B11: Cofre Eletronico Mario? | C11: Não | F11: NOVA | G11: 2021 - FAT04
B12: Chaveiro e placa yoshi mario ver como é o produto | C12: Não | F12: NOVA | G12: 2021 - FAT04
A13: PI4746Y | B13: Caneta com mensagem amor proprio | C13: Sim | D13: INMETRO Artigos Escolares | E13: Destinado para Crianças | F13: NOVA | G13: 2021 - FAT04 | H13: 44111 | I13: Produto precisava de de certificação, com isso seu valor não fechava mais. (Foi considerado como sem certificação por ter custo acima de 0,50 USD por peça, porém esta regra é a do dumping, não da certificação)
B14: BOLSA TÉRMICA HP COM TAG CUSTOMIZÁVEL | C14: Não | F14: NOVA | G14: 2021 - FAT04
A15: PI4799Y | B15: PUFE COM SPEAKER MARIO | C15: Sim | D15: ANATEL MÓDULO BLUETOOTH/WIFI | E15: Bluetooth | F15: NOVA | G15: 2021 - FAT05 | H15: 44138 | I15: Todos projetos da linha MARIO foram cancelados em 03/11, email do Daniel Zhu
A16: PI4783Y | B16: CHAVEIRO DIY MARIO | C16: Sim | D16: INMETRO SISTEMA 7 (LOTE) - PORTARIA 321 | E16: Destinado para Crianças | F16: NOVA | G16: 2021 - FAT05 | H16: 44138 | I16: Todos projetos da linha MARIO foram cancelados em 03/11, email do Daniel Zhu
A17: PI4784Y | B17: CHAVEIRO DIY MARIO | C17: Sim | D17: INMETRO SISTEMA 7 (LOTE) - PORTARIA 321 | E17: Destinado para Crianças | F17: NOVA | G17: 2021 - FAT05 | H17: 44138 | I17: Todos projetos da linha MARIO foram cancelados em 03/11, email do Daniel Zhu
A18: PI4814Y | B18: ESTOJO MARIO | C18: Sim | D18: INMETRO SISTEMA 5 (FABRICA) - PORTARIA 563 | E18: Destinado para Crianças | F18: NOVA | G18: 2021 - FAT05 | H18: 44138 | I18: Todos projetos da linha MARIO foram cancelados em 03/11, email do Daniel Zhu
A19: PI4792Y | B19: HEADPHONE MARIO | C19: Sim | D19: ANATEL MÓDULO BLUETOOTH/WIFI | E19: Bluetooth | F19: NOVA | G19: 2021 - FAT05 | H19: 44138 | I19: Todos projetos da linha MARIO foram cancelados em 03/11, email do Daniel Zhu
A20: PI4793Y | B20: Kit Pipoca Mario | C20: Sim | D20: INMETRO SISTEMA 5 (FABRICA) - PORTARIA 563 | E20: Destinado para Crianças | F20: NOVA | G20: 2021 - FAT05 | H20: 44138 | I20: Todos projetos da linha MARIO foram cancelados em 03/11, email do Daniel Zhu
A21: PI4808Y | B21: almofada biefing livre mario | C21: Sim | D21: INMETRO SISTEMA 5 (FABRICA) - PORTARIA 563 | E21: Destinado para Crianças | F21: NOVA | G21: 2021 - FAT05 | H21: 44138 | I21: Todos projetos da linha MARIO foram cancelados em 03/11, email do Daniel Zhu
B22: Capacete de Bicicleta | C22: Não | D22: Não | E22: OBS | F22: NOVA | G22: 2021 - FAT06 e 7 | I22: A certificação compulsória das bicicletas infantis não contempla itens auxiliares (joelheiras, capacetes, luvas, etc.), limitando-se apenas à bicicleta infantil. Para os itens auxiliares, a certificação é voluntária. Somente capacetes de uso adulto para motocicletas são certificados compulsoriamente no Inmetro. Porém, componentes esportivos para brincadeira, que simulam os de uso profissional, com dimensões diferentes das medidas padrões, são considerados brinquedos.
A23: N/A | B23: Headphone Esquenta Orelha (PI5234Y) | C23: Sim | D23: ANATEL MÓDULO BLUETOOTH/WIFI | E23: Bluetooth | F23: NOVA | G23: 2021 - FAT 05 | H23: 44470 | I23: Corte na verba para compras de itens 2021/2022.
A24: PI5234Y | B24: Carregador wireless neutro (PI5244Y) | C24: Sim | D24: ANATEL MÓDULO BLUETOOTH/WIFI | E24: Carregador | F24: NOVA | G24: 2021 - FAT 05 | H24: 44470 | I24: Corte na verba para compras de itens 2021/2022.
A25: PI5245Y | B25: LuminárIa Carregador wireless Namorados (PI5245Y) | C25: Sim | D25: ANATEL MÓDULO BLUETOOTH/WIFI | E25: Carregador | F25: NOVA | G25: 2021 - FAT 05 | H25: 44470 | I25: Corte na verba para compras de itens 2021/2022.
A26: PI5264Y | B26: Speaker com Alexa (PI5264Y) | C26: Sim | D26: ANATEL MÓDULO BLUETOOTH/WIFI | E26: Bluetooth | F26: NOVA | G26: 2021 - FAT 05 | H26: 44470 | I26: Corte na verba para compras de itens 2021/2022.
A27: PI5279Y | B27: Wireless speaker (PI5279Y) | C27: Sim | D27: ANATEL MÓDULO BLUETOOTH/WIFI | E27: Bluetooth | F27: NOVA | G27: 2021 - FAT 05 | H27: 44470 | I27: Corte na verba para compras de itens 2021/2022.
A28: PI5193Y | B28: Vitrola feminino adulto (PI5193Y) | C28: Sim | D28: ANATEL MÓDULO BLUETOOTH/WIFI | E28: Bluetooth | F28: NOVA | H28: 44470 | I28: Revisão de verba, estratégia e sortimento em loja.
A29: PI5308Y | B29: Fone por Condução ossea (PI5308Y) | C29: Sim | D29: ANATEL MÓDULO BLUETOOTH/WIFI | E29: Bluetooth | F29: NOVA | G29: 2022 - FAT06 | H29: 44529
A30: PI5327Y | B30: Vitrola Movel Retro (PI5327Y) | C30: Sim | D30: ANATEL MÓDULO BLUETOOTH/WIFI | E30: Bluetooth | F30: NOVA | G30: 2022 - FAT06 | H30: 44529
A31: PI5295Y | B31: LUMINARIA WIRELESS URSINHOS CARINHOS | C31: Sim | D31: ANATEL CELULARES | E31: Carregador | F31: NOVA | G31: 2022 - FAT07 | H31: 44529
A32: PI5136Y | B32: SPEAKER E LUMINARIA COM ALCA FITDANCE | C32: Sim | D32: ANATEL MÓDULO BLUETOOTH/WIFI | E32: Bluetooth | F32: NOVA | G32: 2021 - FAT 12 | H32: 44529
A33: PI4006Y | B33: CARREGADOR PORTATIL FRIENDS MOLDURA | C33: Sim | D33: Acessório para Telefone Móvel Celular do tipo Bateria Auxiliar | E33: Power Bank | F33: 8507.60.00 | G33: 2019 - FAT11 | H33: 44501 | I33: Cancelamos os testes, pois ocorreu falha duas vezes e seria obrigatório fazer os ensaios completos novamente, gerando um custo de R$ 4800.
A34: PI5380Y | B34: MINI LUMINARIA OUTROS PERSONAGENS II HP | C34: Sim | D34: INMETRO BRINQUEDOS SISTEMA 5 (FÁBRICA) - PORTARIA 302 | E34: Destinado para Crianças | F34: NOVA | G34: 2021 - FAT 08 | H34: 44593 | I34: Curadoria/Letícia: Devido ao prazo de desenvolvimento e prazo de certificação não vamos conseguir lançar esse item em fat 08 e perderemos a campanha de HP.
A35: PI5399Y | B35: MINI LUMINARIA PERSONAGEM I HP | C35: Sim | D35: INMETRO BRINQUEDOS SISTEMA 5 (FÁBRICA) - PORTARIA 302 | E35: Destinado para Crianças | F35: NOVA | G35: 2021 - FAT 08 | H35: 44593 | I35: Curadoria/Letícia: Devido ao prazo de desenvolvimento e prazo de certificação não vamos conseguir lançar esse item em fat 08 e perderemos a campanha de HP.
A36: PI5414Y | B36: LUMINARIA POMO DE OURO HP | C36: Sim | D36: INMETRO BRINQUEDOS SISTEMA 5 (FÁBRICA) - PORTARIA 302 | E36: Destinado para Crianças | F36: NOVA | G36: 2021 - FAT 08 | H36: 44593
A37: PI5370Y | B37: CHAVEIRO SILICONE UC | C37: Sim | D37: INMETRO BRINQUEDOS SISTEMA 5 (FÁBRICA) - PORTARIA 302 | E37: Destinado para Crianças | F37: NOVA | G37: 2021 - FAT 08 | H37: 44593 | I37: Cancelado - Chaveiro era 3D na parte de cima e de acordo com o OCP, demandaria Certificação como Brinquedos. O Inmetro ainda não retornou nossa consulta.
A38: PI5549Y | B38: JOGO DE DOMINO | C38: Sim | D38: INMETRO BRINQUEDOS SISTEMA 5 (FÁBRICA) - PORTARIA 302 | E38: Destinado para Crianças | F38: NOVA | G38: 2021 - FAT 08 | H38: 44713 | I38: Cancelado - não conseguimos enviar a arte dentro do prazo e não encontramos nenhuma op no catálogo do fornecedor que atendesse nossas expectativas de formato e preço.
A39: CS2160 | B39: JOGO STARTER PACK DO BRASILEIRO | C39: Sim | D39: INMETRO BRINQUEDOS SISTEMA 1b - (LOTE) - PORTARIA 302 | E39: Destinado para Crianças | F39: NOVA | G39: 2021 - FAT 11 | H39: 44805 | I39: Cancelado - Estávamos com o cmv acima da meta e ainda tivemos mais o custo de certificação e isso inviabilizou o produto.
A40: CS2192 | B40: QUEBRA CABECA MAES | C40: Sim | D40: INMETRO BRINQUEDOS SISTEMA 5 (FÁBRICA) - PORTARIA 302 | E40: Destinado para Crianças | F40: NOVA | G40: 2023 - FAT03 | H40: 44805 | I40: Cancelado - motivos de revisão de estratégia de lançamento.
...

Sheet Imaginarium
A1: MARCA | B1: IMAGEM | C1: CÓDIGO | D1: COLEÇÃO | E1: Fornecedor | F1: NOME | G1: NEGÓCIO | H1: TIPO DE CERTIFICAÇÃO | I1: AMOSTRAS NECESSÁRIAS | J1: STATUS | K1: DATA ÚLTIMA ATUALIZAÇÃO (INICIAL, MANUTENÇÃO OU ENCERRAMENTO) | L1: ROTULAGEM | M1: FABRICANTE | N1: Validade da Certificação | O1: Início Manutenção | P1: Número Certificado | Q1: Número Registro / Homologação | R1: OCP / OCD | S1: Possui ISO 9001? | T1: CHEGADA CD | U1: SITUAÇÃO | V1: Descrição E-commerce | W1: Prazo Final Venda
A2: IMAGINARIUM | B2: =HYPERLINK("https://imagens.imgnet.com.br/f/imaginarium/"&C2&";"&C2,image("https://imagens.imgnet.com.br/f/imaginarium/"&C2&"))")) | C2: PI4206Y | D2: 2020 - FAT01 | E2: Greatchip | F2: MALA USB SMART LOCKER CARREGANDO VIAGEM | H2: ANATEL CATEGORIA 2 - MÓDULO BLUETOOTH | I2: 2 unidades | J2: 15/06/21 - Certificado de homologação emitido. | L2: Produto + Manual (ANATEL) | N2: 45070 | O2: =N2-90 -> 44980 | P2: MT-5343/2021 | Q2: 06107-21-12659 | S2: FALSE | T2: =IFERROR(__xludf.DUMMYFUNCTION("IFERROR(VLOOKUP(C2,IMPORTRANGE(""https://docs.google.com/spreadsheets/d/1RmEXtNg60OGvqZjyMxiYNPJ6S_kcz01v57qrHugDWVc/edit#gid=0"",""Chegadas!E:AQ""),19,0),"""")"),"") | U2: Encerrado | W2: =N2 -> 45070
A3: IMAGINARIUM | B3: =HYPERLINK("https://imagens.imgnet.com.br/f/imaginarium/"&C3&";"&C3,image("https://imagens.imgnet.com.br/f/imaginarium/"&C3&"))")) | C3: PI4145Y | D3: 2020 - FAT01 | E3: PETKIT | F3: COMEDOURO SMART PETKIT BRANCO | G3: TECH - HOME TECH | H3: ANATEL CATEGORIA 2 - MÓDULO BLUETOOTH | I3: 2 unidades | J3: 01/06/23 - Certificado suspenso. - 24/06 - Certificado de Homologação emitido. 01/06/21 - Processo cadastrado na Anatel. 31/05/21 - Aprovado o CCT. | L3: Produto + Manual (ANATEL) | N3: 45077 | O3: =N3-90 -> 44987 | P3: MT-5348/2021 | Q3: 07697-21-11541 | S3: FALSE | T3: =IFERROR(__xludf.DUMMYFUNCTION("IFERROR(VLOOKUP(C3,IMPORTRANGE(""https://docs.google.com/spreadsheets/d/1RmEXtNg60OGvqZjyMxiYNPJ6S_kcz01v57qrHugDWVc/edit#gid=0"",""Chegadas!E:AQ""),19,0),"""")"),"") | U3: Encerrado | W3: =N3 -> 45077
A4: IMAGINARIUM | B4: =HYPERLINK("https://imagens.imgnet.com.br/f/imaginarium/"&C4&";"&C4,image("https://imagens.imgnet.com.br/f/imaginarium/"&C4&"))")) | C4: PI3875Y | D4: 2019 - FAT09 | E4: DOULEX | F4: AMPLIFICADOR BLUETOOTH ESTRELA GENIUS | G4: TECH - MUSIC | H4: ANATEL CATEGORIA 2 - MÓDULO BLUETOOTH | I4: 2 unidades | J4: 31/01/2023 -O certificado não será renovado. - 16/06/21 - Certificado de Homologação emitido. | L4: Produto + Manual (ANATEL) | N4: 45072 | O4: =N4-90 -> 44982 | P4: MT-5342/2021 | Q4: 06106-21-12406 | S4: FALSE | T4: =IFERROR(__xludf.DUMMYFUNCTION("IFERROR(VLOOKUP(C4,IMPORTRANGE(""https://docs.google.com/spreadsheets/d/1RmEXtNg60OGvqZjyMxiYNPJ6S_kcz01v57qrHugDWVc/edit#gid=0"",""Chegadas!E:AQ""),19,0),"""")"),"") | U4: Encerrado | W4: =N4 -> 45072
A5: IMAGINARIUM | B5: =HYPERLINK("https://imagens.imgnet.com.br/f/imaginarium/"&C5&";"&C5,image("https://imagens.imgnet.com.br/f/imaginarium/"&C5&"))")) | C5: PI4077Y | D5: 2020 - FAT02 | E5: Hesen | F5: ALMOFADA COELHA VEM QUE TEM | G5: CASA E DECORAÇÃO | H5: INMETRO SISTEMA 5 (FABRICA) - PORTARIA 563 | I5: 36 unidades | J5: Finalizado | L5: Produto + Embalagem (INMETRO) | N5: Certificado encerrado, validade do estoque do produto até 06/07/2023 | P5: IP-BRI-9435-2019-4 | Q5: 001343/2020 | S5: FALSE | T5: =IFERROR(__xludf.DUMMYFUNCTION("IFERROR(VLOOKUP(C5,IMPORTRANGE(""https://docs.google.com/spreadsheets/d/1RmEXtNg60OGvqZjyMxiYNPJ6S_kcz01v57qrHugDWVc/edit#gid=0"",""Chegadas!E:AQ""),19,0),"""")"),"") | U5: Encerrado | V5: Certificação INMETRO:Produto certificado por INNAC OCP 0061 Nº Registro 001343/2020 | W5: =N5 -> Certificado encerrado, validade do estoque do produto até 06/07/2023
A6: IMAGINARIUM | B6: =HYPERLINK("https://imagens.imgnet.com.br/f/imaginarium/"&C6&";"&C6,image("https://imagens.imgnet.com.br/f/imaginarium/"&C6&"))")) | C6: PI4074Y | D6: 2020 - FAT02 | E6: Remember | F6: MALETA DE MAQUIAGEM COM SPEAKER SHOW | G6: TECH | H6: ANATEL CATEGORIA 2 - MÓDULO BLUETOOTH | I6: 2 Amostras completas + 1 Amostra teste lab (Placa PCB com entradas de cabo de RF e Software) | J6: Finalizado | L6: Produto + Manual (ANATEL) | N6: Item não certificado | O6: Homologação ANATEL - Sem necessidade de Auditoria | P6: NA | Q6: NA | S6: FALSE | T6: =IFERROR(__xludf.DUMMYFUNCTION("IFERROR(VLOOKUP(C6,IMPORTRANGE(""https://docs.google.com/spreadsheets/d/1RmEXtNg60OGvqZjyMxiYNPJ6S_kcz01v57qrHugDWVc/edit#gid=0"",""Chegadas!E:AQ""),19,0),"""")"),"") | U6: Encerrado | V6: N/A | W6: =N6 -> Item não certificado
A7: IMAGINARIUM | B7: =HYPERLINK("https://imagens.imgnet.com.br/f/imaginarium/"&C7&";"&C7,image("https://imagens.imgnet.com.br/f/imaginarium/"&C7&"))")) | C7: PI4229Y | D7: 2020 - FAT03 | E7: BAITE | F7: COELHO DE PASCOA INFLAVEL | G7: CASA E DECORAÇÃO | H7: INMETRO SISTEMA 7 (LOTE) - PORTARIA 321 | I7: Aguardando RAM | J7: Finalizado | L7: Produto + Embalagem (INMETRO) | N7: Até o final do lote | O7: Novo desenvolvimento - Analise documental somente das informações de SAC - Sem necessidade de input da ASTEC até manutenção | P7: 5237-2019-BRI -1 | Q7: NA | R7: BRICS OCP 0098 | S7: FALSE | T7: =IFERROR(__xludf.DUMMYFUNCTION("IFERROR(VLOOKUP(C7,IMPORTRANGE(""https://docs.google.com/spreadsheets/d/1RmEXtNg60OGvqZjyMxiYNPJ6S_kcz01v57qrHugDWVc/edit#gid=0"",""Chegadas!E:AQ""),19,0),"""")"),"") | U7: Encerrado | V7: Certificação INMETRO:Produto certificado por BRICS OCP 0098 CE-BRI/BRICS 001180-20 | W7: =N7 -> Até o final do lote
A8: IMAGINARIUM | B8: =HYPERLINK("https://imagens.imgnet.com.br/f/imaginarium/"&C8&";"&C8,image("https://imagens.imgnet.com.br/f/imaginarium/"&C8&"))")) | C8: PI4127Y | D8: 2020 - FAT03 | E8: IPS | F8: MARMITA ELETRICA QUENTE VIU 127V | G8: COMES E BEBES | H8: INMETRO SISTEMA 5 (FABRICA) - PORTARIA 371 | I8: 2 Amostras completas | J8: Finalizado | L8: Produto + Embalagem (INMETRO) | N8: 43892 | P8: 5168/2019-ELE-1 | Q8: NA | R8: BRICS OCP 0098 | S8: TRUE | T8: =IFERROR(__xludf.DUMMYFUNCTION("IFERROR(VLOOKUP(C8,IMPORTRANGE(""https://docs.google.com/spreadsheets/d/1RmEXtNg60OGvqZjyMxiYNPJ6S_kcz01v57qrHugDWVc/edit#gid=0"",""Chegadas!E:AQ""),19,0),"""")"),"") | U8: Encerrado | V8: Certificação INMETRO:Produto certificado por BRICS OCP 0098 Nº Certificado 5168/2019-ELE-1 | W8: =N8 -> 43892
A9: IMAGINARIUM | B9: =HYPERLINK("https://imagens.imgnet.com.br/f/imaginarium/"&C9&";"&C9,image("https://imagens.imgnet.com.br/f/imaginarium/"&C9&"))")) | C9: PI4246Y | D9: 2020 - FAT03 | E9: IPS | F9: MARMITA ELETRICA QUENTE VIU 220V | G9: COMES E BEBES | H9: INMETRO SISTEMA 5 (FABRICA) - PORTARIA 371 | I9: 2 Amostras completas | J9: Finalizado | L9: Produto + Embalagem (INMETRO) | N9: 43892 | P9: 5168/2019-ELE-1 | Q9: NA | R9: BRICS OCP 0098 | S9: TRUE | T9: =IFERROR(__xludf.DUMMYFUNCTION("IFERROR(VLOOKUP(C9,IMPORTRANGE(""https://docs.google.com/spreadsheets/d/1RmEXtNg60OGvqZjyMxiYNPJ6S_kcz01v57qrHugDWVc/edit#gid=0"",""Chegadas!E:AQ""),19,0),"""")"),"") | U9: Encerrado | V9: Certificação INMETRO:Produto certificado por BRICS OCP 0098 Nº Certificado 5168/2019-ELE-1 | W9: =N9 -> 43892
A10: IMAGINARIUM | B10: =HYPERLINK("https://imagens.imgnet.com.br/f/imaginarium/"&C10&";"&C10,image("https://imagens.imgnet.com.br/f/imaginarium/"&C10&"))")) | C10: PI4183Y | D10: 2020 - FAT03 | E10: ED origin | F10: AROMATIZADOR SPEAKER MAE AMOR | G10: COMES E BEBES | H10: INMETRO SISTEMA 5 (FABRICA) - PORTARIA 371 + ANATEL MÓDULO BLUETOOTH | I10: 2 Amostras completas - INMETRO 2 Amostras completas + 1 Amostra teste lab (Placa PCB com entradas de cabo de RF e Software) - ANATEL | J10: Finalizado | L10: Produto + Embalagem + Manual (INMETRO & ANATEL) | N10: 44266 | P10: 5169-2019-ELE-1 | Q10: NA | R10: BRICS OCP 0098 | S10: TRUE | T10: =IFERROR(__xludf.DUMMYFUNCTION("IFERROR(VLOOKUP(C10,IMPORTRANGE(""https://docs.google.com/spreadsheets/d/1RmEXtNg60OGvqZjyMxiYNPJ6S_kcz01v57qrHugDWVc/edit#gid=0"",""Chegadas!E:AQ""),19,0),"""")"),"") | U10: Encerrado | V10: Certificação INMETRO:Produto certificado por BRICS OCP 0098 Nº Certificado 5169-2019-ELE | W10: =N10 -> 44266
A11: IMAGINARIUM | B11: =HYPERLINK("https://imagens.imgnet.com.br/f/imaginarium/"&C11&";"&C11,image("https://imagens.imgnet.com.br/f/imaginarium/"&C11&"))")) | C11: PI4129Y | D11: 2020 - FAT03 | E11: ED origin | F11: AROMATIZADOR SPEAKER MUSICA INSPIRA | G11: CASA E DECORAÇÃO | H11: INMETRO SISTEMA 5 (FABRICA) - PORTARIA 371 + ANATEL MÓDULO BLUETOOTH | I11: 2 Amostras completas - INMETRO 2 Amostras completas + 1 Amostra teste lab (Placa PCB com entradas de cabo de RF e Software) - ANATEL | J11: Finalizado | L11: Produto + Embalagem + Manual (INMETRO & ANATEL) | N11: 44266 | P11: 5169-2019-ELE-1 | Q11: NA | R11: BRICS OCP 0098 | S11: TRUE | T11: =IFERROR(__xludf.DUMMYFUNCTION("IFERROR(VLOOKUP(C11,IMPORTRANGE(""https://docs.google.com/spreadsheets/d/1RmEXtNg60OGvqZjyMxiYNPJ6S_kcz01v57qrHugDWVc/edit#gid=0"",""Chegadas!E:AQ""),19,0),"""")"),"") | U11: Encerrado | V11: Certificação INMETRO:Produto certificado por BRICS OCP 0098 Nº Certificado 5169-2019-ELE | W11: =N11 -> 44266
A12: IMAGINARIUM | B12: =HYPERLINK("https://imagens.imgnet.com.br/f/imaginarium/"&C12&";"&C12,image("https://imagens.imgnet.com.br/f/imaginarium/"&C12&"))")) | C12: PI4219Y | D12: 2020 - FAT04 | E12: TOYLAND | F12: ALMOFADA TE AMO ALIEN DO UNIVERSO | G12: CASA E DECORAÇÃO | H12: INMETRO SISTEMA 7 (LOTE) - PORTARIA 321 | I12: Aguardando RAM | J12: Certificado emitido | L12: Produto ou Embalagem (INMETRO) | N12: Até o final do lote | O12: Novo desenvolvimento - Analise documental somente das informações de SAC - Sem necessidade de input da ASTEC até manutenção | P12: 5269/2020-BRI-1 | Q12: NA | R12: BRICS OCP 0098 | S12: TRUE | T12: =IFERROR(__xludf.DUMMYFUNCTION("IFERROR(VLOOKUP(C12,IMPORTRANGE(""https://docs.google.com/spreadsheets/d/1RmEXtNg60OGvqZjyMxiYNPJ6S_kcz01v57qrHugDWVc/edit#gid=0"",""Chegadas!E:AQ""),19,0),"""")"),"") | U12: Encerrado | V12: Certificação INMETRO:Produto certificado por BRICS OCP 0098 CE-BRI/BRICS 001180-20 | W12: =N12 -> Até o final do lote
A13: IMAGINARIUM | B13: =HYPERLINK("https://imagens.imgnet.com.br/f/imaginarium/"&C13&";"&C13,image("https://imagens.imgnet.com.br/f/imaginarium/"&C13&"))")) | C13: PI4207Y | D13: 2021 - FAT06 | E13: ANC China | F13: LOCALIZADOR DE CHAVE PRETO | G13: TECH | H13: ANATEL CATEGORIA 2 - MÓDULO BLUETOOTH | I13: 2 Amostras completas + 1 Amostra teste lab (Placa PCB com entradas de cabo de RF e Software) | J13: 22/12 - Não teremos venda sell-in e nem recompra desses itens. Certificado não será renovado. - Finalizado | L13: Produto + Manual (ANATEL) | N13: 45021 | O13: Homologação ANATEL - Sem necessidade de Auditoria | P13: MT-5263/2021 | Q13: 03511-21-12855 | S13: FALSE | T13: =IFERROR(__xludf.DUMMYFUNCTION("IFERROR(VLOOKUP(C13,IMPORTRANGE(""https://docs.google.com/spreadsheets/d/1RmEXtNg60OGvqZjyMxiYNPJ6S_kcz01v57qrHugDWVc/edit#gid=0"",""Chegadas!E:AQ""),19,0),"""")"),"") | U13: Encerrado | V13: Produto homologado pela Anatel: Nº Homologação 03511-21-12855 | W13: =N13 -> 45021
A14: IMAGINARIUM | B14: =HYPERLINK("https://imagens.imgnet.com.br/f/imaginarium/"&C14&";"&C14,image("https://imagens.imgnet.com.br/f/imaginarium/"&C14&"))")) | C14: PI4257Y | D14: 2020 - FAT04 | E14: Donghao | F14: KARAOKE PORTATIL FAZ AO VIVO | G14: TECH | H14: ANATEL CATEGORIA 2 - MÓDULO BLUETOOTH | I14: 2 Amostras completas + 1 Amostra teste lab (Placa PCB com entradas de cabo de RF e Software) | J14: Finalizado | L14: Produto + Manual (ANATEL) | N14: 44247 | O14: Homologação ANATEL - Sem necessidade de Auditoria | P14: NA | Q14: NA | S14: FALSE | T14: =IFERROR(__xludf.DUMMYFUNCTION("IFERROR(VLOOKUP(C14,IMPORTRANGE(""https://docs.google.com/spreadsheets/d/1RmEXtNg60OGvqZjyMxiYNPJ6S_kcz01v57qrHugDWVc/edit#gid=0"",""Chegadas!E:AQ""),19,0),"""")"),"") | U14: Encerrado | V14: N/A | W14: =N14 -> 44247
A15: IMAGINARIUM | B15: =HYPERLINK("https://imagens.imgnet.com.br/f/imaginarium/"&C15&";"&C15,image("https://imagens.imgnet.com.br/f/imaginarium/"&C15&"))")) | C15: PI4217Y | D15: 2020 - FAT04 | E15: Hesen | F15: KIT PIPOCA DUPLO SERIE KILLER | G15: COMES E BEBES | H15: INMETRO SISTEMA 5 (FABRICA) - PORTARIA 563 | I15: Aguardando RAM | J15: Finalizado | L15: Produto + Embalagem (INMETRO) | N15: 44050 | O15: 44020 | P15: IPI-BRI-9951-2019-05 | Q15: 002937/2020 | S15: TRUE | T15: =IFERROR(__xludf.DUMMYFUNCTION("IFERROR(VLOOKUP(C15,IMPORTRANGE(""https://docs.google.com/spreadsheets/d/1RmEXtNg60OGvqZjyMxiYNPJ6S_kcz01v57qrHugDWVc/edit#gid=0"",""Chegadas!E:AQ""),19,0),"""")"),"") | U15: Encerrado | V15: Certificação INMETRO:Produto certificado por INNAC OCP 0061 Nº Registro 002937/2020 | W15: =N15 -> 44050
A16: IMAGINARIUM | B16: =HYPERLINK("https://imagens.imgnet.com.br/f/imaginarium/"&C16&";"&C16,image("https://imagens.imgnet.com.br/f/imaginarium/"&C16&"))")) | C16: PI4255Y | D16: 2020 - FAT04 | E16: Sun Lin | F16: PIANO GIGANTE DO RE MI | G16: CASA E DECORAÇÃO | H16: INMETRO SISTEMA 7 (LOTE) - PORTARIA 321 | I16: Aguardando RAM | J16: Certificado emitido | L16: Produto + Embalagem (INMETRO) | N16: Até o final do lote | O16: Novo desenvolvimento - Analise documental somente das informações de SAC - Sem necessidade de input da ASTEC até manutenção | P16: 5236-2019-BRI-1 | Q16: NA | R16: BRICS OCP 0098 | S16: FALSE | T16: =IFERROR(__xludf.DUMMYFUNCTION("IFERROR(VLOOKUP(C16,IMPORTRANGE(""https://docs.google.com/spreadsheets/d/1RmEXtNg60OGvqZjyMxiYNPJ6S_kcz01v57qrHugDWVc/edit#gid=0"",""Chegadas!E:AQ""),19,0),"""")"),"") | U16: Encerrado | V16: Certificação INMETRO:Produto certificado por BRICS OCP 0098 CE-BRI/BRICS 001180-20 | W16: =N16 -> Até o final do lote
A17: IMAGINARIUM | B17: =HYPERLINK("https://imagens.imgnet.com.br/f/imaginarium/"&C17&";"&C17,image("https://imagens.imgnet.com.br/f/imaginarium/"&C17&"))")) | C17: PI4193Y | D17: 2020 - FAT04 | E17: Robotime | F17: QUEBRA CABEÇA 3D DINOSSAURO ROBO | G17: CASA E DECORAÇÃO | H17: INMETRO SISTEMA 7 (LOTE) - PORTARIA 321 | I17: Aguardando RAM | J17: Certificado emitido | L17: Produto + Embalagem (INMETRO) | N17: Até o final do lote | O17: Novo desenvolvimento - Analise documental somente das informações de SAC - Sem necessidade de input da ASTEC até manutenção | P17: 5238/2019-BRI-1 | Q17: NA | R17: BRICS OCP 0098 | S17: FALSE | T17: =IFERROR(__xludf.DUMMYFUNCTION("IFERROR(VLOOKUP(C17,IMPORTRANGE(""https://docs.google.com/spreadsheets/d/1RmEXtNg60OGvqZjyMxiYNPJ6S_kcz01v57qrHugDWVc/edit#gid=0"",""Chegadas!E:AQ""),19,0),"""")"),"") | U17: Encerrado | V17: Certificação INMETRO:Produto certificado por BRICS OCP 0098 CE-BRI/BRICS 001180-20 | W17: =N17 -> Até o final do lote
A18: IMAGINARIUM | C18: LY2877 | D18: 2020 - FAT04 | E18: Hesen | F18: ALMOFADA MANIA URSO VALENTIM ME LEVA | G18: CASA E DECORAÇÃO | H18: INMETRO SISTEMA 7 (LOTE) - PORTARIA 321 | I18: 18 Amostras | J18: Certificado emitido, já destinado ao CD | L18: Embalagem (INMETRO) | N18: Até o final do lote | O18: Novo desenvolvimento - Analise documental somente das informações de SAC - Sem necessidade de input da ASTEC até manutenção | P18: 5450-2020-BRI-1 | Q18: NA | R18: BRICS OCP 0098 | S18: TRUE | T18: =IFERROR(__xludf.DUMMYFUNCTION("IFERROR(VLOOKUP(C18,IMPORTRANGE(""https://docs.google.com/spreadsheets/d/1RmEXtNg60OGvqZjyMxiYNPJ6S_kcz01v57qrHugDWVc/edit#gid=0"",""Chegadas!E:AQ""),19,0),"""")"),"") | U18: Encerrado | V18: LUDI | W18: =N18 -> Até o final do lote
A19: IMAGINARIUM | B19: =HYPERLINK("https://imagens.imgnet.com.br/f/imaginarium/"&C19&";"&C19,image("https://imagens.imgnet.com.br/f/imaginarium/"&C19&"))")) | C19: PI4220Y | D19: 2020 - FAT04 | E19: Hesen | F19: ALMOFADA SARDADINHA DE VOCE | G19: CASA E DECORAÇÃO | H19: INMETRO SISTEMA 5 (FABRICA) - PORTARIA 563 | I19: Já separadas | J19: Finalizado | L19: Produto + Embalagem (INMETRO) | N19: Até o final do lote | O19: Novo desenvolvimento - Analise documental somente das informações de SAC - Sem necessidade de input da ASTEC até manutenção | P19: 5617/2020-BRI-1 | Q19: NA | R19: BRICS OCP 0098 | S19: TRUE | T19: =IFERROR(__xludf.DUMMYFUNCTION("IFERROR(VLOOKUP(C19,IMPORTRANGE(""https://docs.google.com/spreadsheets/d/1RmEXtNg60OGvqZjyMxiYNPJ6S_kcz01v57qrHugDWVc/edit#gid=0"",""Chegadas!E:AQ""),19,0),"""")"),"") | U19: Encerrado | V19: Certificação INMETRO:Produto certificado por BRICS OCP 0098 CE-BRI/BRICS 001180-20 | W19: =N19 -> Até o final do lote
A20: IMAGINARIUM | B20: =HYPERLINK("https://imagens.imgnet.com.br/f/imaginarium/"&C20&";"&C20,image("https://imagens.imgnet.com.br/f/imaginarium/"&C20&"))")) | C20: PI4306Y | D20: 2020 - FAT06 | E20: Yopinshi | F20: KIT ACESSORIOS TECH JUNTO E CONECTADO | G20: TECH | H20: ANATEL CATEGORIA 1 - CELULARES | I20: 2 Amostras completas + 1 Amostra teste lab (Placa PCB com entradas de cabo de RF e Software) | J20: Finalizado | L20: Produto (ANATEL) | N20: 44370 | O20: Homologação ANATEL - Sem necessidade de Auditoria | P20: NA | Q20: NA | S20: TRUE | T20: =IFERROR(__xludf.DUMMYFUNCTION("IFERROR(VLOOKUP(C20,IMPORTRANGE(""https://docs.google.com/spreadsheets/d/1RmEXtNg60OGvqZjyMxiYNPJ6S_kcz01v57qrHugDWVc/edit#gid=0"",""Chegadas!E:AQ""),19,0),"""")"),"") | U20: Encerrado | V20: NA | W20: =N20 -> 44370
A21: IMAGINARIUM | B21: =HYPERLINK("https://imagens.imgnet.com.br/f/imaginarium/"&C21&";"&C21,image("https://imagens.imgnet.com.br/f/imaginarium/"&C21&"))")) | C21: PI4214Y | D21: 2020 - FAT04 | E21: Chuyang | F21: ORGANIZADOR E CARREGADOR SEM FIO CORTICA | G21: TECH | H21: ANATEL CATEGORIA 1 - CELULARES | I21: 2 Amostras completas + 1 Amostra teste lab (Placa PCB com entradas de cabo de RF e Software) | J21: Finalizado | L21: Produto + Manual (ANATEL) | N21: Item não certificado | O21: Homologação ANATEL - Sem necessidade de Auditoria | P21: NA | Q21: NA | S21: TRUE | T21: =IFERROR(__xludf.DUMMYFUNCTION("IFERROR(VLOOKUP(C21,IMPORTRANGE(""https://docs.google.com/spreadsheets/d/1RmEXtNg60OGvqZjyMxiYNPJ6S_kcz01v57qrHugDWVc/edit#gid=0"",""Chegadas!E:AQ""),19,0),"""")"),"") | U21: Encerrado | V21: N/A | W21: =N21 -> Item não certificado
A22: IMAGINARIUM | B22: =HYPERLINK("https://imagens.imgnet.com.br/f/imaginarium/"&C22&";"&C22,image("https://imagens.imgnet.com.br/f/imaginarium/"&C22&"))")) | C22: PI4308Y | D22: 2020 - FAT06 | E22: Huazeng | F22: LUMINARIA SPEAKER BUD | G22: TECH | H22: ANATEL CATEGORIA 2 - MÓDULO BLUETOOTH | I22: 2 Amostras completas + 1 Amostra teste lab (Placa PCB com entradas de cabo de RF e Software) | J22: Certificado Emitido Registro: 07231-20-12851 Criação já alinhou a aplicação das artes | L22: Produto + Manual (ANATEL) | N22: Item não certificado | O22: Homologação ANATEL - Sem necessidade de Auditoria | P22: NA | Q22: NA | S22: FALSE | T22: =IFERROR(__xludf.DUMMYFUNCTION("IFERROR(VLOOKUP(C22,IMPORTRANGE(""https://docs.google.com/spreadsheets/d/1RmEXtNg60OGvqZjyMxiYNPJ6S_kcz01v57qrHugDWVc/edit#gid=0"",""Chegadas!E:AQ""),19,0),"""")"),"") | U22: Encerrado | V22: N/A | W22: =N22 -> Item não certificado
A23: IMAGINARIUM | B23: =HYPERLINK("https://imagens.imgnet.com.br/f/imaginarium/"&C23&";"&C23,image("https://imagens.imgnet.com.br/f/imaginarium/"&C23&"))")) | C23: PI4259Y | D23: 2020 - FAT05 | E23: Hangzhou Shouyi I/E CO,,LTD | F23: CESTA DE BASQUETE COM LED JOGADA CERTA | G23: CASA E DECORAÇÃO | H23: INMETRO SISTEMA 7 (LOTE) - PORTARIA 321 | I23: 10 Amostras Completas | J23: Certificado recebido e anûencia deferida, processo de certificação finalizado. | L23: Embalagem (INMETRO) | N23: Até o final do lote | O23: Sem necessidade - Certificação de Lote | P23: 5637-2020-BRI-1 | Q23: NA | R23: BRICS OCP 0098 | S23: FALSE | T23: =IFERROR(__xludf.DUMMYFUNCTION("IFERROR(VLOOKUP(C23,IMPORTRANGE(""https://docs.google.com/spreadsheets/d/1RmEXtNg60OGvqZjyMxiYNPJ6S_kcz01v57qrHugDWVc/edit#gid=0"",""Chegadas!E:AQ""),19,0),"""")"),"") | U23: Encerrado | V23: Certificação INMETRO:Produto certificado por BRICS OCP 0098 CE-BRI/BRICS 001180-20 | W23: =N23 -> Até o final do lote
A24: IMAGINARIUM | B24: =HYPERLINK("https://imagens.imgnet.com.br/f/imaginarium/"&C24&";"&C24,image("https://imagens.imgnet.com.br/f/imaginarium/"&C24&"))")) | C24: PI4586Y | D24: 2020 - FAT10 | E24: Universe Sound | F24: FONE DE OUVIDO SEM FIO ESCUTA AQUI | G24: TECH | H24: ANATEL CATEGORIA 2 - MÓDULO BLUETOOTH | I24: 1 Amostras completas + 1 Amostra teste lab (Placa PCB com entradas de cabo de RF e Software) | J24: 01/06/2023 - Certificado suspenso. - Amostras enviadas para o laboratório (Eldorado) em 17/06, finalizando pendências documentais com o certificador para obtermos o número de registro ANATEL que deve conter no produto. Ensaios finalizados Registro emitido:08894-20-12418 | L24: Produto + Manual (ANATEL) | N24: 45077 | O24: =N24-90 -> 44987 | P24: MT-5347/2021 | Q24: 06109-21-12418 | S24: TRUE | T24: =IFERROR(__xludf.DUMMYFUNCTION("IFERROR(VLOOKUP(C24,IMPORTRANGE(""https://docs.google.com/spreadsheets/d/1RmEXtNg60OGvqZjyMxiYNPJ6S_kcz01v57qrHugDWVc/edit#gid=0"",""Chegadas!E:AQ""),19,0),"""")"),"") | U24: Encerrado | V24: Produto homologado pela Anatel: Nº Homologação 06109-21-12418 | W24: =N24 -> 45077
A25: IMAGINARIUM | B25: =HYPERLINK("https://imagens.imgnet.com.br/f/imaginarium/"&C25&";"&C25,image("https://imagens.imgnet.com.br/f/imaginarium/"&C25&"))")) | C25: PI4587Y | D25: 2020 - FAT10 | E25: Universe Sound | F25: FONE DE OUVIDO SEM FIO OUVIR | G25: TECH | H25: ANATEL CATEGORIA 2 - MÓDULO BLUETOOTH | I25: 1 Amostras completas + 1 Amostra teste lab (Placa PCB com entradas de cabo de RF e Software) | J25: 01/06/2023 - Certificado suspenso. - Amostras enviadas para o laboratório (Eldorado) em 17/06, finalizando pendências documentais com o certificador para obtermos o número de registro ANATEL que deve conter no produto. Ensaios finalizados Registro emitido:08894-20-12418 | L25: Produto + Manual (ANATEL) | N25: 45077 | O25: =N25-90 -> 44987 | P25: MT-5347/2021 | Q25: 06109-21-12418 | S25: TRUE | T25: =IFERROR(__xludf.DUMMYFUNCTION("IFERROR(VLOOKUP(C25,IMPORTRANGE(""https://docs.google.com/spreadsheets/d/1RmEXtNg60OGvqZjyMxiYNPJ6S_kcz01v57qrHugDWVc/edit#gid=0"",""Chegadas!E:AQ""),19,0),"""")"),"") | U25: Encerrado | V25: Produto homologado pela Anatel: Nº Homologação 06109-21-12418 | W25: =N25 -> 45077
A26: IMAGINARIUM | B26: =HYPERLINK("https://imagens.imgnet.com.br/f/imaginarium/"&C26&";"&C26,image("https://imagens.imgnet.com.br/f/imaginarium/"&C26&"))")) | C26: PI4511Y | D26: 2022 - FAT05 | E26: Joy rain | F26: CANETA MUDA FRASES HP FEITICOS | G26: USO PESSOAL | H26: INMETRO SISTEMA 5 (FABRICA) - PORTARIA 481 | I26: 50 Amostras | J26: 23/04/2025 - Manutenção finalizada. 03/06/24 - Manutenção concluída. Retrabalho das canetas concluído. | K26: 45770 | L26: Embalagem (INMETRO) | N26: 46153 | O26: =N26-90 -> 46063 | P26: 9114/2023-AE-1 | Q26: 004671/2023 | R26: BRICS OCP 0098 | S26: TRUE | T26: =IFERROR(__xludf.DUMMYFUNCTION("IFERROR(VLOOKUP(C26,IMPORTRANGE(""https://docs.google.com/spreadsheets/d/1RmEXtNg60OGvqZjyMxiYNPJ6S_kcz01v57qrHugDWVc/edit#gid=0"",""Chegadas!E:AQ""),19,0),"""")"),44686.0) -> 44686 | U26: Ativo | V26: Certificação INMETRO:Produto certificado por BRICS OCP 0098 Nº Registro 004671/2023 | W26: =IFERROR(IF(U26="Ativo","Ativo",IF(U26="SKU excluído","Vencido",VLOOKUP(C26,Encerramentos!B:G,6,0))),"") -> Ativo
A27: IMAGINARIUM | B27: =HYPERLINK("https://imagens.imgnet.com.br/f/imaginarium/"&C27&";"&C27,image("https://imagens.imgnet.com.br/f/imaginarium/"&C27&"))")) | C27: PI4499Y | D27: 2020 - FAT09 | E27: Joy rain | F27: CANETA MUDA FRASES FRIENDS MOLDURA | G27: USO PESSOAL | H27: INMETRO SISTEMA 5 (FABRICA) - PORTARIA 481 | I27: 0 Amostras, (amostras da caneta HP foram ensaiadas no processo) | J27: 21/08/23 - Certificado encerrado. - Retrabalho das Canetas concluído em 23/11 | L27: Embalagem (INMETRO) | N27: 45788 | O27: =N27-90 -> 45698 | P27: 5605/2020-AE-1 | Q27: 006550/2020 | R27: BRICS OCP 0098 | S27: TRUE | T27: =IFERROR(__xludf.DUMMYFUNCTION("IFERROR(VLOOKUP(C27,IMPORTRANGE(""https://docs.google.com/spreadsheets/d/1RmEXtNg60OGvqZjyMxiYNPJ6S_kcz01v57qrHugDWVc/edit#gid=0"",""Chegadas!E:AQ""),19,0),"""")"),"") | U27: Encerrado | V27: Certificação INMETRO:Produto certificado por BRICS OCP 0098 Nº Registro 006550/2020 | W27: =N27 -> 45788
A28: IMAGINARIUM | B28: =HYPERLINK("https://imagens.imgnet.com.br/f/imaginarium/"&C28&";"&C28,image("https://imagens.imgnet.com.br/f/imaginarium/"&C28&"))")) | C28: PI4628Y | D28: 2021 - FAT01 | E28: AUBADI | F28: MOUSE SEM FIO GLITTER DEIXAR ROLAR | G28: USO PESSOAL | H28: ANATEL CATEGORIA 2 - MÓDULO BLUETOOTH | I28: 1 Amostras completas + 1 Amostra teste lab (Placa PCB com entradas de cabo de RF e Software) | J28: 21/05 - Homologação Anatel finalizada. 23/04 - Processo cadastrado na Anatel. 12/04 - Em análise pela engenharia da OCD - previsão 16/05 24/03 - Entrega dos relatórios prevista para 12/04 e finalização homologação 16/05. Amostras chegaram no laboratório em 17/09. Nº de Registro já recebido e encaminhado para fornecedor incluir no produto 14600-20-13387 | L28: Produto + Manual (ANATEL) | N28: 45038 | O28: =N28-90 -> 44948 | P28: MT-5057/2020 | Q28: 14600-20-13387 | S28: FALSE | T28: =IFERROR(__xludf.DUMMYFUNCTION("IFERROR(VLOOKUP(C28,IMPORTRANGE(""https://docs.google.com/spreadsheets/d/1RmEXtNg60OGvqZjyMxiYNPJ6S_kcz01v57qrHugDWVc/edit#gid=0"",""Chegadas!E:AQ""),19,0),"""")"),"") | U28: Encerrado | V28: Produto homologado pela Anatel: Nº Homologação 14600-20-13387 | W28: =N28 -> 45038
A29: IMAGINARIUM | B29: =HYPERLINK("https://imagens.imgnet.com.br/f/imaginarium/"&C29&";"&C29,image("https://imagens.imgnet.com.br/f/imaginarium/"&C29&"))")) | C29: PI4630Y | D29: 2021 - FAT01 | E29: AUBADI | F29: MOUSE SEM FIO GLITTER AMEI | G29: USO PESSOAL | H29: ANATEL CATEGORIA 2 - MÓDULO BLUETOOTH | I29: 1 Amostras completas + 1 Amostra teste lab (Placa PCB com entradas de cabo de RF e Software) | J29: 21/05 - Homologação Anatel finalizada. 23/04 - Processo cadastrado na Anatel. 12/04 - Em análise pela engenharia da OCD - previsão 16/05 24/03 - Entrega dos relatórios prevista para 12/04 e finalização homologação 16/05. Amostras chegaram no laboratório em 17/09. Nº de Registro já recebido e encaminhado para fornecedor incluir no produto 14600-20-13387 | L29: Produto + Manual (ANATEL) | N29: 45038 | O29: =N29-90 -> 44948 | P29: MT-5057/2020 | Q29: 14600-20-13387 | S29: FALSE | T29: =IFERROR(__xludf.DUMMYFUNCTION("IFERROR(VLOOKUP(C29,IMPORTRANGE(""https://docs.google.com/spreadsheets/d/1RmEXtNg60OGvqZjyMxiYNPJ6S_kcz01v57qrHugDWVc/edit#gid=0"",""Chegadas!E:AQ""),19,0),"""")"),"") | U29: Encerrado | V29: Produto homologado pela Anatel: Nº Homologação 14600-20-13387 | W29: =N29 -> 45038
A30: IMAGINARIUM | B30: =HYPERLINK("https://imagens.imgnet.com.br/f/imaginarium/"&C30&";"&C30,image("https://imagens.imgnet.com.br/f/imaginarium/"&C30&"))")) | C30: PI1172Y PI1183Y PI3716Y | D30: 2021 - FAT01 | E30: NIHAO | F30: Nihao Familia 1 - Manutenção dos produtos | G30: USO PESSOAL | H30: INMETRO SISTEMA 5 (FABRICA) - PORTARIA 481 | I30: Aguardando RAM | J30: Transfererência do Certificado do INNAC para a Brics concluída, avançando para envio das amostras para teste LI Prévia deferida pelo INMETRO | L30: Embalagem (INMETRO) | N30: 44231 | O30: 44025 | P30: 000910/2015 | Q30: IP-AESC-3847/2019-01 IP-AESC-3847/2019-02 | S30: TRUE | T30: =IFERROR(__xludf.DUMMYFUNCTION("IFERROR(VLOOKUP(C30,IMPORTRANGE(""https://docs.google.com/spreadsheets/d/1RmEXtNg60OGvqZjyMxiYNPJ6S_kcz01v57qrHugDWVc/edit#gid=0"",""Chegadas!E:AQ""),19,0),"""")"),"") | U30: Encerrado | W30: =N30 -> 44231
A31: IMAGINARIUM | B31: =HYPERLINK("https://imagens.imgnet.com.br/f/imaginarium/"&C31&";"&C31,image("https://imagens.imgnet.com.br/f/imaginarium/"&C31&"))")) | C31: PI4642Y | D31: 2021 - FAT01 | E31: JYK | F31: VITROLA DE MALA BLUETOOTH AMARELA | G31: TECH | H31: ANATEL CATEGORIA 2 - MÓDULO BLUETOOTH | I31: 1 Amostras completas + 1 Amostra teste lab (Placa PCB com entradas de cabo de RF e Software) | J31: 10/01/23 - Planejamento informou que não deseja renovar o certificado. - Amostra chegou em 28/09 em SP, foi enviada para ensaios laboratoriais em 30/09. Número de registro recebido em 29/10. ANATEL: 15743-20-13462 | L31: Produto + Manual (ANATEL) | N31: 45007 | O31: =N31-90 -> 44917 | P31: MT-5084/2020 | Q31: 15743-20-13462 | S31: TRUE | T31: =IFERROR(__xludf.DUMMYFUNCTION("IFERROR(VLOOKUP(C31,IMPORTRANGE(""https://docs.google.com/spreadsheets/d/1RmEXtNg60OGvqZjyMxiYNPJ6S_kcz01v57qrHugDWVc/edit#gid=0"",""Chegadas!E:AQ""),19,0),"""")"),"") | U31: Encerrado | V31: Este produto contém a placa ST226A código de homologação ANATEL 15743-20-13462 | W31: =N31 -> 45007
A32: IMAGINARIUM | B32: =HYPERLINK("https://imagens.imgnet.com.br/f/imaginarium/"&C32&";"&C32,image("https://imagens.imgnet.com.br/f/imaginarium/"&C32&"))")) | C32: PI4669Y | D32: 2021 - FAT10 | E32: Wallesun | F32: AROMATIZADOR E UMIDIFICADOR NO AR | G32: CASA E DECORAÇÃO | H32: INMETRO Eletrodomésticos | I32: 2 amostras para ensaios na China | J32: Documentação recebida e encaminhada para análise do OCP. Aguardando confirmação do laboratório para envio das amostras e confirmação do OCP quanto a etiqueta de Certificação para alinhamento com o time de criação. Amostras Chegaram no FEDEX 772035901130 Aprovação da Etiqueta concedida pelo OCP. Relatório preliminar do laboratório agendado para dia 18/12. Tipo de certificação alterada para Lote em função do fornecedor não conseguir cumprir com os requisitos minímos cobrados pelo laboratório. Embarque será agendado após a conclusão dos ensaios preliminares. Ensaios preliminares concluídos e instrução de embarque encaminhada para o time da China Previsão da emissão do certificado 22/01 21/01 - Recebemos o Draft do Certificado e demos ok para emissão, devemos receber o certificado assinado amanhã dia 22/01 28/01 - Certificado emitido. Processo liberado pela RFB. | L32: Produto + Embalagem (INMETRO) | N32: Até o final do lote | O32: Sem auditoria - lote | P32: 6926/2021-ELE-1 | Q32: N/A | R32: BRICS OCP 0098 | S32: FALSE | T32: =IFERROR(__xludf.DUMMYFUNCTION("IFERROR(VLOOKUP(C32,IMPORTRANGE(""https://docs.google.com/spreadsheets/d/1RmEXtNg60OGvqZjyMxiYNPJ6S_kcz01v57qrHugDWVc/edit#gid=0"",""Chegadas!E:AQ""),19,0),"""")"),44474.0) -> 44474 | U32: Encerrado | V32: Certificação INMETRO:Produto certificado por BRICS OCP 0098 Nº Certificado 6356/2020-ELE | W32: =N32 -> Até o final do lote
A33: IMAGINARIUM | B33: =HYPERLINK("https://imagens.imgnet.com.br/f/imaginarium/"&C33&";"&C33,image("https://imagens.imgnet.com.br/f/imaginarium/"&C33&"))")) | C33: PI4732Y | D33: 2021 - FAT03 | E33: Iceberg | F33: MINI GELADEIRA PARA COSMETICOS LILAS | G33: TECH | H33: INMETRO Eletrodomésticos | I33: 2 amostras para ensaios na China | J33: 10/11 - Certificado encerrado: Informado pela empresa que o prazo para que estes produtos sejam comercializados é de 15 meses contados da data de 10/11/2021, para Cooler Elétrico modelo PI4732Y possui 461 unidades em estoque . -- 05/02 - Certificado emitido - validade: 04/02/2024. etiquetagem ok Documentação recebida e encaminhada para análise do OCP. Aguardando confirmação do laboratório para envio das amostras e confirmação do OCP quanto a etiqueta de Certificação para alinhamento com o time de criação Aprovação da Etiqueta concedida pelo OCP. Ensaios com previsão de término em 04/01, produção em massa irá seguir após a conclusão dos ensaios. Draft de Ensaios recebido em 06/01 e aprovados na mesma data, aguardando finalização da análise pelo time técnico do OCP para confirmamos a conformidade dos ensaios e seguir com a produção do produto. 08/01 - Recebemos a confirmação dos ensaios e o relatório final já seguiu para emissão, asim que tivermos o mesmo vamos seguir para obter o Certificado de Conformidade 20/01 - Validação de documentos realizada, aguardando envio do draft do certificado. 26/01 - Certificado cobrado novamente 03/02 - Draft do Certificado recebido 04/02 - Draft aprovado. | L33: Produto + Embalagem (INMETRO) | N33: 44597 | O33: =N33-90 -> 44507 | P33: 6364/2020-ELE-1 | Q33: N/A | R33: BRICS OCP 0098 | S33: TRUE | T33: =IFERROR(__xludf.DUMMYFUNCTION("IFERROR(VLOOKUP(C33,IMPORTRANGE(""https://docs.google.com/spreadsheets/d/1RmEXtNg60OGvqZjyMxiYNPJ6S_kcz01v57qrHugDWVc/edit#gid=0"",""Chegadas!E:AQ""),19,0),"""")"),"") | U33: Encerrado | V33: Certificação INMETRO:Produto certificado por BRICS OCP 0098 Nº Certificado 6364/2020-ELE-1 | W33: =N33 -> 44597
A34: IMAGINARIUM | B34: =HYPERLINK("https://imagens.imgnet.com.br/f/imaginarium/"&C34&";"&C34,image("https://imagens.imgnet.com.br/f/imaginarium/"&C34&"))")) | C34: PI4368Y | D34: 2020 - FAT08 | E34: Hesen | F34: ALMOFADA SONORA HP CHAPEU SELETOR | G34: CASA E DECORAÇÃO | H34: INMETRO SISTEMA 7 (LOTE) - PORTARIA 321 | I34: Amostras enviadas para laboratório, aguardando finalização dos ensaios laboratoriais | J34: 09/03 - Certificado emitido. Aguardando estar disponível no Orquestra para anuência da LI (10 dias - 30/03, chega dia 02/04 no Brasil). Novo processo de certificação de lote, já aberto com a Brics Certificações, data de conclusão da produção em massa solicitada para a China para averiguarmos a data para amostragem das peças a serem ensaiadas 11/01 - Confirmação da conclusão da Mass Production em 29/01, verificar se é possível pegar amostras do lote antes, quantas deverão ser produzidas, e qual a data de embarque para ver se o prazo está de acordo 21/01 - Combinado com o OCP a coleta antecipada, aguardando retorno da antecipação de amostras. Embarque agendado para o dia 06/02 no processo 1739_SH 05/02 - Amostra coletada, já está no Cobo. Proposta ensaio aprovada. Previsão de relatório 26/02. | L34: Produto + Embalagem (INMETRO) | N34: Até o final do lote | O34: Sem auditoria - lote | P34: 6544/2021-BRI | Q34: N/A | R34: BRICS OCP 0098 | S34: TRUE | T34: =IFERROR(__xludf.DUMMYFUNCTION("IFERROR(VLOOKUP(C34,IMPORTRANGE(""https://docs.google.com/spreadsheets/d/1RmEXtNg60OGvqZjyMxiYNPJ6S_kcz01v57qrHugDWVc/edit#gid=0"",""Chegadas!E:AQ""),19,0),"""")"),"") | U34: Encerrado | V34: Certificação INMETRO:Produto certificado por BRICS OCP 0098 CE-BRI/BRICS 001180-20 | W34: =N34 -> Até o final do lote
A35: IMAGINARIUM | B35: =HYPERLINK("https://imagens.imgnet.com.br/f/imaginarium/"&C35&";"&C35,image("https://imagens.imgnet.com.br/f/imaginarium/"&C35&"))")) | C35: PI4461Y | D35: 2020 - FAT08 | E35: KYC | F35: CARREGADOR SEM FIO HP PLATAFORMA 9 3/4 | G35: TECH | H35: ANATEL CATEGORIA 1 - CELULARES | I35: 2 Amostras completas | J35: 27/10/23 - O certificado não será renovado. 07/03/22 - Manutenção do Certificado realizada. -- 12/03 - Certificado de homologação emitido pela ANATEL. Precisamos etiquetar 10 unidades deste lote. Documentos submetidos para a ANATEL. Previsão homologação repassada pela OCP: 15/03. Recompra de produto, solicitação de compras de etiquetas realizada, previsão de envio para 28/12. Assim que recebidas serão encaminhadas via FedEx para time na China. Código de homologação emitido: 09318-20-12562 - Compra das etiquetas realizadas e recebidas pelo Guilherme em 04/01/2021, encaminhadas para China via FedEx em 05/01/2021 - Tracking: 772527892413 12/01 - Confirmação de FAT 04 recebida | L35: Produto + Manual (ANATEL) | M35: Shenzhen Kaiyue Century Techonology Co. LTD | N35: 45355 | O35: =N35-90 -> 45265 | P35: MT-4968/2020 | Q35: 09318-20-12562 | S35: TRUE | T35: =IFERROR(__xludf.DUMMYFUNCTION("IFERROR(VLOOKUP(C35,IMPORTRANGE(""https://docs.google.com/spreadsheets/d/1RmEXtNg60OGvqZjyMxiYNPJ6S_kcz01v57qrHugDWVc/edit#gid=0"",""Chegadas!E:AQ""),19,0),"""")"),44474.0) -> 44474 | U35: Encerrado | V35: Produto homologado pela Anatel: Nº Homologação 09318-20-1256 | W35: =N35 -> 45355
A36: IMAGINARIUM | B36: =HYPERLINK("https://imagens.imgnet.com.br/f/imaginarium/"&C36&";"&C36,image("https://imagens.imgnet.com.br/f/imaginarium/"&C36&"))")) | C36: PI4717Y | D36: 2021 - FAT03 | E36: Pic value | F36: CESTA DE PICNIC COM AMPLIFICADOR CESTOU | G36: TECH | H36: ANATEL MÓDULO BLUETOOTH | I36: 2 Amostras completas + 1 Amostra teste lab (Placa PCB com entradas de cabo de RF e Software) | J36: 10/01/23 - Certificado não será renovado. - 19/05 - Homologação finalizada. 07/05 - Processo cadastrado na Anatel. 07/04 - Nova amostra está no laboratório, entrega dos relatórios prevista para 28/04 e finalização homologação 30/05. Nova amostra enviada por Fedex tracking number: 773271403014 - nova data de finalização estimada 30/05 17/03 - Cobramos novamente a equipe da China resposta sobre o firmware. Os testes estão marcados para 22/03, entrega laudos 26/03 e homologação prevista para estar ok em 01/05. Amostra retirada do Laboratório, está na Eagle Tech para configuração. Previsão de finalização de relatórios dos testes: 26/03 e homologação: 01/05. Documentos recebidos, encaminhados para o OCD confirmar se podemos reutilizar o módulo anterior. Confirmação recebida, poderemos reutilizar o código ANATEL 05882-19-04646 | L36: Produto + Manual (ANATEL) | N36: 45052 | O36: =N36-90 -> 44962 | P36: MT-5258/2021 | Q36: 03460-21-13781 | S36: FALSE | T36: =IFERROR(__xludf.DUMMYFUNCTION("IFERROR(VLOOKUP(C36,IMPORTRANGE(""https://docs.google.com/spreadsheets/d/1RmEXtNg60OGvqZjyMxiYNPJ6S_kcz01v57qrHugDWVc/edit#gid=0"",""Chegadas!E:AQ""),19,0),"""")"),"") | U36: Encerrado | V36: Este produto contém a placa SL-272 código de homologação ANATEL 03460-21-13781 | W36: =N36 -> 45052
A37: IMAGINARIUM | B37: =HYPERLINK("https://imagens.imgnet.com.br/f/imaginarium/"&C37&";"&C37,image("https://imagens.imgnet.com.br/f/imaginarium/"&C37&"))")) | C37: PI4225Y | D37: 2021 - FAT04 | E37: Wantong | F37: FONDUE ELETRICO COM JOGO VAI ESQUENTAR | G37: COMES E BEBES | H37: INMETRO Eletrodomésticos | I37: 2 amostras para ensaios no Brasil | J37: Seguindo com o encerramento da certificação 01/02 - CANCELAMENTO DA MANUNTEÇÃO SOLICITADO (sem recompras posteriores a esta para justificar) - chegou no CD hoje. Renovação de Certificado, projeto já iniciado com certificador, amostras para testes compradas pelo Danilo, serão encaminhadas para o Laboratório no retorno após o recesso de final de ano em 04/01/2021. 08/01 - Recebemos ok para envio das amostras e as mesmas já foram encaminhadas para o lab 21/01 - Datas para auditoria da Manuntenção agendadas, produto já encaminhado para embarque no dia 25/01 | L37: Selo de certificação na embalagem e no produto | N37: 44286 | O37: =N37-90 -> 44196 | P37: 5319/2020-ELE-1 | Q37: N/A | R37: BRICS OCP 0098 | S37: FALSE | T37: =IFERROR(__xludf.DUMMYFUNCTION("IFERROR(VLOOKUP(C37,IMPORTRANGE(""https://docs.google.com/spreadsheets/d/1RmEXtNg60OGvqZjyMxiYNPJ6S_kcz01v57qrHugDWVc/edit#gid=0"",""Chegadas!E:AQ""),19,0),"""")"),"") | U37: Encerrado | V37: Certificação INMETRO:Produto certificado por BRICS OCP 0098 Nº Certificado 5319/2020-ELE | W37: =N37 -> 44286
A38: IMAGINARIUM | B38: =HYPERLINK("https://imagens.imgnet.com.br/f/imaginarium/"&C38&";"&C38,image("https://imagens.imgnet.com.br/f/imaginarium/"&C38&"))")) | C38: PI4750Y | D38: 2021 - FAT04 | E38: Kingstar | F38: GARRAFA COM AMPLIFICADOR SENTE A BATIDA | G38: TECH | H38: ANATEL CATEGORIA 2 - MÓDULO BLUETOOTH | I38: 2 Amostras completas + 1 Amostra teste lab (Placa PCB com entradas de cabo de RF e Software) | J38: 22/12 - Não teremos venda sell-in e nem recompra desses itens. Certificado não será renovado. - 12/04 - Homologação Anatel finalizada. 01/04 - Processo submetido a Anatel. 15/03 - Amostra encaminhada ao lab. Previsão de finalização de relatórios dos testes: 26/03 e homologação: 02/05. Primeira documentação reecbida em 10/12 após a confirmação de compra. Fora do prazo normal e FAT em risco. Amostra foi enviada para o Brasil da China no dia 18/12, Rastreio 772413404017, encaminhada para o laboratório em 06/01/2021. Previsão para recebermos o código ANATEL em 15/01. 15/01 - Número ANATEL emitido e artes encaminhadas para o time da China - ANATEL: 00427-21-13647 21/01 - Questionamento se o produto vai pegar FAT 04 encaminhado 22/01 - Produto confirmado para FAT 04 03/02 - Por problemas de produção o produto vai para FAT 05 17/02 - Amostra recebida pelo laboratório. Relatório deve estar pronto dia 26/02 (aguardando confirmação de agenda do Lab); | L38: Produto + Manual (ANATEL) | N38: 45017 | O38: =N38-90 -> 44927 | P38: MT-5157/2021 | Q38: 00427-21-13647 | S38: FALSE | T38: =IFERROR(__xludf.DUMMYFUNCTION("IFERROR(VLOOKUP(C38,IMPORTRANGE(""https://docs.google.com/spreadsheets/d/1RmEXtNg60OGvqZjyMxiYNPJ6S_kcz01v57qrHugDWVc/edit#gid=0"",""Chegadas!E:AQ""),19,0),"""")"),"") | U38: Encerrado | V38: Este produto contém a placa PI4750Y código de homologação ANATEL 00427-21-13647 | W38: =N38 -> 45017
A39: IMAGINARIUM | B39: =HYPERLINK("https://imagens.imgnet.com.br/f/imaginarium/"&C39&";"&C39,image("https://imagens.imgnet.com.br/f/imaginarium/"&C39&"))")) | C39: PI4764Y | D39: 2021 - FAT04 | E39: freesun | F39: PROJETOR PORTATIL TRAGO IMAGENS | G39: TECH | H39: ANATEL CATEGORIA 2 - MÓDULO BLUETOOTH | I39: 2 Amostras completas + 1 Amostra teste lab (Placa PCB com entradas de cabo de RF e Software) | J39: 19/01/23 - Projetores estão sem estoque no CD, certificado não será renovado. - 21/05 - Homologação Anatel finalizada. 12/05 - Processo submetido a Anatel - previsão homologação 12/06. 07/05 - Recebidos os laudos, em análise da Engenharia da Master. 12/04 - Amostra recebida e em preparo, início dos testes: 26/04 e entrega dos laudos 07/05. Finalização homologação prevista para 12/06. Vamos enviar a placa do produto final para configuração - nova data de finalização estimada 30/05 Tracking OM946335005BR 17/03 - Empresa que está configurando a placa solicitou algumas informações para o fornecedor (e-mail enviado ontem 16/03). Precisamos de retorno para os testes que serão realizados em 26/03. Previsão homologação 07/05. -atende namorados? 12/03 - Projetor da qualidade não é o mesmo. Vamos homologar a placa. Ensaios agendados no Laboratório, relatórios estarão prontos em 01/04. Homologação: 07/05. 09/03 - Amostra está na Eagle Tech para configuração, Bruno informou que a placa está danificada (queimada). Temos que enviar o projetor que está na qualidade para SP. Documentos Recebidos em 04/11 e encaminhados para o OCD Amostras Chegaram no FEDEX 772035901130. ANATEL 16942-20-13646 21/01 - Produto pode passar por mudanças e perder funcionalidade BT, solicitação da nova documentação encaminhada para avaliar se manteremos o mesmo número ANATEL 26/01 - Documentação é idêntica ao do modelo anterior, materemos o código | L39: Produto + Manual (ANATEL) | N39: 45058 | O39: =N39-90 -> 44968 | P39: MT-5268/2021 | Q39: 03906-21-13799 | S39: FALSE | T39: =IFERROR(__xludf.DUMMYFUNCTION("IFERROR(VLOOKUP(C39,IMPORTRANGE(""https://docs.google.com/spreadsheets/d/1RmEXtNg60OGvqZjyMxiYNPJ6S_kcz01v57qrHugDWVc/edit#gid=0"",""Chegadas!E:AQ""),19,0),"""")"),"") | U39: Encerrado | V39: Este produto contém a placa PI4764Y código de homologação ANATEL 03906-21-13799 | W39: =N39 -> 45058
A40: IMAGINARIUM | B40: =HYPERLINK("https://imagens.imgnet.com.br/f/imaginarium/"&C40&";"&C40,image("https://imagens.imgnet.com.br/f/imaginarium/"&C40&"))")) | C40: PI4197Y | D40: 2020 - FAT04 | E40: Huazeng | F40: LUMINARIA CARREGADOR SEM FIO OFFICE | G40: TECH | H40: ANATEL CATEGORIA 1 - CELULARES | I40: Amostras enviadas para laboratório, aguardando finalização dos ensaios laboratoriais | J40: 15/02/2023 - Confirmado por e-mail que não seguiremos com a renovação desse certificado. 21/07/2022 - Certificado atualizado, nova data de validade: 21/05/2024. 07/05 - Homologação Anatel finalizada. 24/05 - Processo cadastrado na Anatel. 21/05 - Recebido o CCT, sistema da Anatel está fora e não conseguimos cadastrar o processo hoje. 10/05 - Em análise pela OCD, previsão homologação 05/06. 26/04 - Item entregue no laboratório. Testes serão iniciados em 30/04, laudos entregues em 11/05. Finalização homologação prevista paa 05/06. 06/04 - Enviamos novas amostras para o laboratório. Estimativa de homologação atualizada para 04/06. 01/04 - Amostra com problema, laboratório tentou repetir o ensaio de Imunidade à ESD em outra amostra, porém ela não está funcionando adequadamente para o ensaio. Não está reconhecendo o touch. 08/03 - Previsão de entrega dos relatórios do laboratório: 31/03.Sem data de embarque definida. Estimativa homologação 04/05. Recompra de produto, solicitação de compras de etiquetas realizada, previsão de envio para 28/12. Assim que recebidas serão encaminhadas via FedEx para time na China. Código de homologação emitido: 05161-20-12355 - Compra das etiquetas realizadas e recebidas pelo Guilherme em 04/01/2021, encaminhadas para China via FedEx em 05/01/2021 - Tracking: 772527892413 06/01 - Produto confirmado para FAT 05 | L40: Produto + Manual (ANATEL) | M40: Shenzhen Huazeng Technology Co., Ltd | N40: 45433 | O40: =N40-90 -> 45343 | P40: MT-5341/2021 | Q40: 06105-21-12851 | R40: MASTER | S40: TRUE | T40: =IFERROR(__xludf.DUMMYFUNCTION("IFERROR(VLOOKUP(C40,IMPORTRANGE(""https://docs.google.com/spreadsheets/d/1RmEXtNg60OGvqZjyMxiYNPJ6S_kcz01v57qrHugDWVc/edit#gid=0"",""Chegadas!E:AQ""),19,0),"""")"),"") | U40: Encerrado | V40: Produto homologado pela Anatel: Nº Homologação 06105-21-12851 | W40: =N40 -> 45433
...

Sheet Puket
A1: MARCA | B1: IMAGEM | C1: CÓDIGO | D1: COLEÇÃO | E1: Fornecedor | F1: NOME | G1: NEGÓCIO | H1: TIPO DE CERTIFICAÇÃO | I1: AMOSTRAS NECESSÁRIAS | J1: STATUS | K1: DATA ÚLTIMA ATUALIZAÇÃO (INICIAL, MANUTENÇÃO OU ENCERRAMENTO) | L1: ROTULAGEM | M1: FABRICANTE | N1: Validade da Certificação | O1: Início Manutenção | P1: Número Certificado | Q1: Número Registro / Homologação | R1: Possui ISO 9001? | S1: CHEGADA CD | T1: SITUAÇÃO | U1: Descrição E-commerce | V1: Prazo Final Venda
A2: PUKET | C2: 100400403 | D2: 2023 HIGH SUMMER | E2: TOYLAND | F2: ALMOFADA PELUCIA UNICORNIO | G2: AÇÃO PROMOCIONAL | H2: INMETRO BRINQUEDOS SISTEMA 5 (FÁBRICA) - PORTARIA 302 | I2: 9 Amostras | J2: 26/10/23 - Isabela: De acordo com os emails da Isadora, essa certificação foi encerrada. 22/06 - Número de Registro concedido. 13/06 - Número de Registro solicitado nesta data. 08/06 - Certificado de Conformidade emitido. 06/05 - Coleta confirmada, auditoria da fábrica prevista para 12/05. | L2: Produto (selo Inmetro + advertências) | N2: 45085 | O2: =N2-90 -> 44995 | P2: 7796/2022-BRI-1 | Q2: 006561/2022 | R2: TRUE | S2: =IFERROR(__xludf.DUMMYFUNCTION("VLOOKUP(C2,importrange(""https://docs.google.com/spreadsheets/d/1fN1Q8KwrSYW55JpWNgQQ61JbS3zg1Ft2OqML6ziwN_Q/edit#gid=1174286835"",""PreCons!J:V""),13,0)"),"#N/A") -> #N/A | T2: Encerrado | U2: Certificação INMETRO: Produto certificado por BRICS OCP 0098 Nº Registro 006561/2022 | V2: =IFERROR(IF(T2="Ativo","Ativo",IF(T2="SKU excluído","Vencido",VLOOKUP(C2,Encerramentos!B:G,6,0))),"") -> 45869
A3: PUKET | C3: 100400402 | D3: 2023 HIGH SUMMER | E3: TOYLAND | F3: ALMOFADA PELUCIA DINOSSAURO | G3: AÇÃO PROMOCIONAL | H3: INMETRO BRINQUEDOS SISTEMA 5 (FÁBRICA) - PORTARIA 302 | I3: 9 Amostras | J3: 26/10/23 - Isabela: De acordo com os emails da Isadora, essa certificação foi encerrada. 22/06 - Número de Registro concedido. 13/06 - Número de Registro solicitado nesta data. 08/06 - Certificado de Conformidade emitido. 06/05 - Coleta confirmada, auditoria da fábrica prevista para 12/05. | L3: Produto (selo Inmetro + advertências) | N3: 45085 | O3: =N3-90 -> 44995 | P3: 7796/2022-BRI-1 | Q3: 006561/2022 | R3: TRUE | S3: =IFERROR(__xludf.DUMMYFUNCTION("VLOOKUP(C3,importrange(""https://docs.google.com/spreadsheets/d/1fN1Q8KwrSYW55JpWNgQQ61JbS3zg1Ft2OqML6ziwN_Q/edit#gid=1174286835"",""PreCons!J:V""),13,0)"),"#N/A") -> #N/A | T3: Encerrado | U3: Certificação INMETRO: Produto certificado por BRICS OCP 0098 Nº Registro 006561/2022 | V3: =IFERROR(IF(T3="Ativo","Ativo",IF(T3="SKU excluído","Vencido",VLOOKUP(C3,Encerramentos!B:G,6,0))),"") -> 45869
A4: PUKET | C4: 100400416 | D4: 2023 HIGH SUMMER | E4: Kayuan | F4: HEADPHONE BLUETOOTH GIRLS - COLOR BLOCK | G4: AÇÃO PROMOCIONAL | H4: ANATEL CATEGORIA 2 - MÓDULO BLUETOOTH | I4: 0 Amostras | J4: 30/08 - Certificado de Homologação emitido. Chegada CD: 07/10. 29/08 - Status na Anatel: Em análise - RE. 26/08 - Efetuado o upload dos arquivos na Anatel e solicitado retorno quanto à inclusão dos novos modelos. 26/07 - Enviados documentos para Master, aguardando retorno referente a inclusão. 15/06 - Solicitadas fotos internas e externas dos modelos para enviar ao OCD. | L4: Produto + Manual (ANATEL) | N4: 45151 | O4: =N4-90 -> 45061 | P4: MT-5533/2021 | Q4: 09550-21-11617 | R4: TRUE | S4: =IFERROR(__xludf.DUMMYFUNCTION("VLOOKUP(C4,importrange(""https://docs.google.com/spreadsheets/d/1fN1Q8KwrSYW55JpWNgQQ61JbS3zg1Ft2OqML6ziwN_Q/edit#gid=1174286835"",""PreCons!J:V""),13,0)"),"#N/A") -> #N/A | T4: Encerrado | U4: Este produto está homologado pela Anatel de acordo com os procedimentos regulamentados para avaliação da conformidade de produtos para telecomunicações e atende aos requisitos técnicos aplicados, sendo referenciado pelo código de homologação Anatel: 09550-21-11617. Para maiores informações, consulte o site da ANATEL em www.anatel.gov.br | V4: =N4 -> 45151
A5: PUKET | C5: 100400417 | D5: 2023 HIGH SUMMER | E5: Kayuan | F5: HEADPHONE BLUETOOTH BOYS - COLOR BLOCK | G5: AÇÃO PROMOCIONAL | H5: ANATEL CATEGORIA 2 - MÓDULO BLUETOOTH | I5: 0 Amostras | J5: 30/08 - Certificado de Homologação emitido. Chegada CD: 07/10. 29/08 - Status na Anatel: Em análise - RE. 26/08 - Efetuado o upload dos arquivos na Anatel e solicitado retorno quanto à inclusão dos novos modelos. 26/07 - Enviados documentos para Master, aguardando retorno referente a inclusão. 15/06 - Solicitadas fotos internas e externas dos modelos para enviar ao OCD. | L5: Produto + Manual (ANATEL) | N5: 45151 | O5: =N5-90 -> 45061 | P5: MT-5533/2021 | Q5: 09550-21-11617 | R5: TRUE | S5: =IFERROR(__xludf.DUMMYFUNCTION("VLOOKUP(C5,importrange(""https://docs.google.com/spreadsheets/d/1fN1Q8KwrSYW55JpWNgQQ61JbS3zg1Ft2OqML6ziwN_Q/edit#gid=1174286835"",""PreCons!J:V""),13,0)"),"#N/A") -> #N/A | T5: Encerrado | U5: Este produto está homologado pela Anatel de acordo com os procedimentos regulamentados para avaliação da conformidade de produtos para telecomunicações e atende aos requisitos técnicos aplicados, sendo referenciado pelo código de homologação Anatel: 09550-21-11617. Para maiores informações, consulte o site da ANATEL em www.anatel.gov.br | V5: =N5 -> 45151
A6: PUKET | B6: =HYPERLINK("https://imagens.imgnet.com.br/f/imaginarium/"&C6&";"&C6,image("https://imagens.imgnet.com.br/f/imaginarium/"&C6&"))")) | E6: Joy Rain | F6: JoyRain Familia 01 - Lápis Grafite JoyRain Familia 02 - Caneta Esferográfica (LED) JoyRain Familia 03 - Borracha | G6: ACESSÓRIOS | H6: INMETRO SISTEMA 5 (FABRICA) - PORTARIA 481 | L6: Embalagem (INMETRO) | N6: 45198 | O6: =N6-90 -> 45108 | P6: IP-AESC-3488/2020-01 IP-AESC-3488/2020-02 IP-AESC-3488/2020-03 | Q6: 006914/2020 006680/2020 006682/2020 | R6: FALSE | S6: =IFERROR(__xludf.DUMMYFUNCTION("VLOOKUP(C6,importrange(""https://docs.google.com/spreadsheets/d/1fN1Q8KwrSYW55JpWNgQQ61JbS3zg1Ft2OqML6ziwN_Q/edit#gid=1174286835"",""PreCons!J:V""),13,0)"),"#N/A") -> #N/A | T6: Encerrado | V6: =N6 -> 45198
